[2025-05-26T14:47:59.338+0000] {taskinstance.py:1957} INFO - Dependencies all met for dep_context=non-requeueable deps ti=<TaskInstance: ptt_macshop_scraper.extract_ptt_articles scheduled__2025-05-25T00:00:00+00:00 [queued]>
[2025-05-26T14:47:59.343+0000] {taskinstance.py:1957} INFO - Dependencies all met for dep_context=requeueable deps ti=<TaskInstance: ptt_macshop_scraper.extract_ptt_articles scheduled__2025-05-25T00:00:00+00:00 [queued]>
[2025-05-26T14:47:59.343+0000] {taskinstance.py:2171} INFO - Starting attempt 1 of 1
[2025-05-26T14:47:59.351+0000] {taskinstance.py:2192} INFO - Executing <Task(PythonOperator): extract_ptt_articles> on 2025-05-25 00:00:00+00:00
[2025-05-26T14:47:59.354+0000] {standard_task_runner.py:60} INFO - Started process 72 to run task
[2025-05-26T14:47:59.356+0000] {standard_task_runner.py:87} INFO - Running: ['***', 'tasks', 'run', 'ptt_macshop_scraper', 'extract_ptt_articles', 'scheduled__2025-05-25T00:00:00+00:00', '--job-id', '14', '--raw', '--subdir', 'DAGS_FOLDER/ptt_macshop_dag.py', '--cfg-path', '/tmp/tmp7qmaw4r4']
[2025-05-26T14:47:59.359+0000] {standard_task_runner.py:88} INFO - Job 14: Subtask extract_ptt_articles
[2025-05-26T14:47:59.392+0000] {task_command.py:423} INFO - Running <TaskInstance: ptt_macshop_scraper.extract_ptt_articles scheduled__2025-05-25T00:00:00+00:00 [running]> on host 471bda57ed4c
[2025-05-26T14:47:59.436+0000] {taskinstance.py:2481} INFO - Exporting env vars: AIRFLOW_CTX_DAG_OWNER='***' AIRFLOW_CTX_DAG_ID='ptt_macshop_scraper' AIRFLOW_CTX_TASK_ID='extract_ptt_articles' AIRFLOW_CTX_EXECUTION_DATE='2025-05-25T00:00:00+00:00' AIRFLOW_CTX_TRY_NUMBER='1' AIRFLOW_CTX_DAG_RUN_ID='scheduled__2025-05-25T00:00:00+00:00'
[2025-05-26T14:47:59.447+0000] {taskinstance.py:2699} ERROR - Task failed with exception
Traceback (most recent call last):
  File "/home/airflow/.local/lib/python3.8/site-packages/urllib3/connection.py", line 174, in _new_conn
    conn = connection.create_connection(
  File "/home/airflow/.local/lib/python3.8/site-packages/urllib3/util/connection.py", line 72, in create_connection
    for res in socket.getaddrinfo(host, port, family, socket.SOCK_STREAM):
  File "/usr/local/lib/python3.8/socket.py", line 918, in getaddrinfo
    for res in _socket.getaddrinfo(host, port, family, type, proto, flags):
socket.gaierror: [Errno -2] Name or service not known

During handling of the above exception, another exception occurred:

Traceback (most recent call last):
  File "/home/airflow/.local/lib/python3.8/site-packages/urllib3/connectionpool.py", line 715, in urlopen
    httplib_response = self._make_request(
  File "/home/airflow/.local/lib/python3.8/site-packages/urllib3/connectionpool.py", line 404, in _make_request
    self._validate_conn(conn)
  File "/home/airflow/.local/lib/python3.8/site-packages/urllib3/connectionpool.py", line 1058, in _validate_conn
    conn.connect()
  File "/home/airflow/.local/lib/python3.8/site-packages/urllib3/connection.py", line 363, in connect
    self.sock = conn = self._new_conn()
  File "/home/airflow/.local/lib/python3.8/site-packages/urllib3/connection.py", line 186, in _new_conn
    raise NewConnectionError(
urllib3.exceptions.NewConnectionError: <urllib3.connection.HTTPSConnection object at 0xffff9b3b8b50>: Failed to establish a new connection: [Errno -2] Name or service not known

During handling of the above exception, another exception occurred:

Traceback (most recent call last):
  File "/home/airflow/.local/lib/python3.8/site-packages/requests/adapters.py", line 486, in send
    resp = conn.urlopen(
  File "/home/airflow/.local/lib/python3.8/site-packages/urllib3/connectionpool.py", line 799, in urlopen
    retries = retries.increment(
  File "/home/airflow/.local/lib/python3.8/site-packages/urllib3/util/retry.py", line 592, in increment
    raise MaxRetryError(_pool, url, error or ResponseError(cause))
urllib3.exceptions.MaxRetryError: HTTPSConnectionPool(host='www.ptt.cc', port=443): Max retries exceeded with url: /bbs/MacShop/index.html (Caused by NewConnectionError('<urllib3.connection.HTTPSConnection object at 0xffff9b3b8b50>: Failed to establish a new connection: [Errno -2] Name or service not known'))

During handling of the above exception, another exception occurred:

Traceback (most recent call last):
  File "/home/airflow/.local/lib/python3.8/site-packages/airflow/models/taskinstance.py", line 433, in _execute_task
    result = execute_callable(context=context, **execute_callable_kwargs)
  File "/home/airflow/.local/lib/python3.8/site-packages/airflow/operators/python.py", line 199, in execute
    return_value = self.execute_callable()
  File "/home/airflow/.local/lib/python3.8/site-packages/airflow/operators/python.py", line 216, in execute_callable
    return self.python_callable(*self.op_args, **self.op_kwargs)
  File "/opt/airflow/dags/ptt_macshop_dag.py", line 23, in extract_articles
    res = requests.get(url, cookies=cookies)
  File "/home/airflow/.local/lib/python3.8/site-packages/requests/api.py", line 73, in get
    return request("get", url, params=params, **kwargs)
  File "/home/airflow/.local/lib/python3.8/site-packages/requests/api.py", line 59, in request
    return session.request(method=method, url=url, **kwargs)
  File "/home/airflow/.local/lib/python3.8/site-packages/requests/sessions.py", line 589, in request
    resp = self.send(prep, **send_kwargs)
  File "/home/airflow/.local/lib/python3.8/site-packages/requests/sessions.py", line 703, in send
    r = adapter.send(request, **kwargs)
  File "/home/airflow/.local/lib/python3.8/site-packages/requests/adapters.py", line 519, in send
    raise ConnectionError(e, request=request)
requests.exceptions.ConnectionError: HTTPSConnectionPool(host='www.ptt.cc', port=443): Max retries exceeded with url: /bbs/MacShop/index.html (Caused by NewConnectionError('<urllib3.connection.HTTPSConnection object at 0xffff9b3b8b50>: Failed to establish a new connection: [Errno -2] Name or service not known'))
[2025-05-26T14:47:59.464+0000] {taskinstance.py:1138} INFO - Marking task as FAILED. dag_id=ptt_macshop_scraper, task_id=extract_ptt_articles, execution_date=20250525T000000, start_date=20250526T144759, end_date=20250526T144759
[2025-05-26T14:47:59.472+0000] {standard_task_runner.py:107} ERROR - Failed to execute job 14 for task extract_ptt_articles (HTTPSConnectionPool(host='www.ptt.cc', port=443): Max retries exceeded with url: /bbs/MacShop/index.html (Caused by NewConnectionError('<urllib3.connection.HTTPSConnection object at 0xffff9b3b8b50>: Failed to establish a new connection: [Errno -2] Name or service not known')); 72)
[2025-05-26T14:47:59.496+0000] {local_task_job_runner.py:234} INFO - Task exited with return code 1
[2025-05-26T14:47:59.506+0000] {taskinstance.py:3281} INFO - 0 downstream tasks scheduled from follow-on schedule check
